<sdf version='1.11'>
  <model name='wamv'>
    <link name='base_footprint'>
      <inertial>
        <pose>-0.010332621914388119 0 0.24583324608384011 0 0 0</pose>
        <mass>248.33000000000001</mass>
        <inertia>
          <ixx>224.52717583472031</ixx>
          <ixy>0</ixy>
          <ixz>-3.2359464261265258</ixz>
          <iyy>451.38310669015033</iyy>
          <iyz>0</iyz>
          <izz>502.93825152542979</izz>
        </inertia>
      </inertial>
      <collision name='base_footprint_fixed_joint_lump__base_link_collision'>
        <pose>0 0 1.25 0 0 0</pose>
        <geometry>
          <box>
            <size>1.8500000000000001 1 0.10000000000000001</size>
          </box>
        </geometry>
      </collision>
      <collision name='base_footprint_fixed_joint_lump__base_link_collision_1'>
        <pose>-0.40000000000000002 1.03 0.20000000000000001 0 1.5707963267948966 0</pose>
        <geometry>
          <cylinder>
            <length>4</length>
            <radius>0.20000000000000001</radius>
          </cylinder>
        </geometry>
      </collision>
      <collision name='base_footprint_fixed_joint_lump__base_link_collision_2'>
        <pose>1.8500000000000001 1.03 0.29999999999999999 0 1.3799999999999997 0</pose>
        <geometry>
          <cylinder>
            <length>0.5</length>
            <radius>0.17000000000000001</radius>
          </cylinder>
        </geometry>
      </collision>
      <collision name='base_footprint_fixed_joint_lump__base_link_collision_3'>
        <pose>2.2999999999999998 1.03 0.40000000000000002 0 1.3 0</pose>
        <geometry>
          <cylinder>
            <length>0.45000000000000001</length>
            <radius>0.12</radius>
          </cylinder>
        </geometry>
      </collision>
      <collision name='base_footprint_fixed_joint_lump__base_link_collision_4'>
        <pose>-0.40000000000000002 -1.03 0.20000000000000001 0 1.5707963267948966 0</pose>
        <geometry>
          <cylinder>
            <length>4</length>
            <radius>0.20000000000000001</radius>
          </cylinder>
        </geometry>
      </collision>
      <collision name='base_footprint_fixed_joint_lump__base_link_collision_5'>
        <pose>1.8500000000000001 -1.03 0.29999999999999999 0 1.3799999999999997 0</pose>
        <geometry>
          <cylinder>
            <length>0.5</length>
            <radius>0.17000000000000001</radius>
          </cylinder>
        </geometry>
      </collision>
      <collision name='base_footprint_fixed_joint_lump__base_link_collision_6'>
        <pose>2.2999999999999998 -1.03 0.40000000000000002 0 1.3 0</pose>
        <geometry>
          <cylinder>
            <length>0.45000000000000001</length>
            <radius>0.12</radius>
          </cylinder>
        </geometry>
      </collision>
      <collision name='base_footprint_fixed_joint_lump__battery_dx_link_collision_7'>
        <pose>-0.14999999999999999 -1.0289999999999999 0.60299999999999998 0 0 0</pose>
        <geometry>
          <box>
            <size>0.64000000000000001 0.44 0.31</size>
          </box>
        </geometry>
      </collision>
      <collision name='base_footprint_fixed_joint_lump__battery_sx_link_collision_8'>
        <pose>-0.14999999999999999 1.0289999999999999 0.60299999999999998 0 0 0</pose>
        <geometry>
          <box>
            <size>0.64000000000000001 0.44 0.31</size>
          </box>
        </geometry>
      </collision>
      <collision name='base_footprint_fixed_joint_lump__cpu_cases_link_collision_9'>
        <pose>0.17299999999999999 0 1.5349999999999999 0 0 0</pose>
        <geometry>
          <box>
            <size>0.59499999999999997 0.82999999999999996 0.46999999999999997</size>
          </box>
        </geometry>
        <surface>
          <contact>
            <ode/>
          </contact>
          <friction>
            <ode/>
          </friction>
        </surface>
      </collision>
      <collision name='base_footprint_fixed_joint_lump__cpu_cases_link_collision_10'>
        <pose>-0.314 0 1.4399999999999999 0 0 0</pose>
        <geometry>
          <box>
            <size>0.375 0.64000000000000001 0.28000000000000003</size>
          </box>
        </geometry>
        <surface>
          <contact>
            <ode/>
          </contact>
          <friction>
            <ode/>
          </friction>
        </surface>
      </collision>
      <collision name='base_footprint_fixed_joint_lump__tripod_legs_collision_collision_11'>
        <pose>0.77000000000000002 0 1.3999999999999999 0 0 0</pose>
        <geometry>
          <cylinder>
            <length>0.218</length>
            <radius>0.10000000000000001</radius>
          </cylinder>
        </geometry>
      </collision>
      <collision name='base_footprint_fixed_joint_lump__tripod_ring_collision_collision_12'>
        <pose>0.77000000000000002 0 1.5129999999999999 0 0 0</pose>
        <geometry>
          <cylinder>
            <length>0.01</length>
            <radius>0.068000000000000005</radius>
          </cylinder>
        </geometry>
      </collision>
      <collision name='base_footprint_fixed_joint_lump__lidar_collision_collision_13'>
        <pose>0.77000000000000002 0 1.554 0 0 0</pose>
        <geometry>
          <cylinder>
            <length>0.071999999999999995</length>
            <radius>0.051499999999999997</radius>
          </cylinder>
        </geometry>
      </collision>
      <visual name='base_footprint_fixed_joint_lump__base_link_visual'>
        <pose>0 0 0 0 0 0</pose>
        <geometry>
          <mesh>
            <scale>1 1 1</scale>
            <uri>file:///home/luca002/proj_ws/src/wamv_gazebo/models/wam-v/meshes/WAM-V-Base.dae</uri>
          </mesh>
        </geometry>
      </visual>
      <visual name='base_footprint_fixed_joint_lump__battery_dx_link_visual_1'>
        <pose>-0.13 -1.0289999999999999 0.44800000000000001 0 0 0</pose>
        <geometry>
          <mesh>
            <scale>1 1 1</scale>
            <uri>file:///home/luca002/proj_ws/src/wamv_gazebo/models/wam-v/meshes/battery.dae</uri>
          </mesh>
        </geometry>
      </visual>
      <visual name='base_footprint_fixed_joint_lump__battery_sx_link_visual_2'>
        <pose>-0.13 1.0289999999999999 0.44800000000000001 0 0 0</pose>
        <geometry>
          <mesh>
            <scale>1 1 1</scale>
            <uri>file:///home/luca002/proj_ws/src/wamv_gazebo/models/wam-v/meshes/battery.dae</uri>
          </mesh>
        </geometry>
      </visual>
      <visual name='base_footprint_fixed_joint_lump__cpu_cases_link_visual_3'>
        <pose>0.072999999999999995 0 1.3 0 0 0</pose>
        <geometry>
          <mesh>
            <scale>1 1 1</scale>
            <uri>file:///home/luca002/proj_ws/src/wamv_gazebo/models/wam-v/meshes/cpu_cases.dae</uri>
          </mesh>
        </geometry>
      </visual>
      <visual name='base_footprint_fixed_joint_lump__tripod_legs_visual_visual_4'>
        <pose>0.77000000000000002 0 1.29 0 0 0</pose>
        <geometry>
          <mesh>
            <scale>1 1 1</scale>
            <uri>file:///home/luca002/proj_ws/src/wamv_gazebo/models/wam-v/meshes/legs.dae</uri>
          </mesh>
        </geometry>
        <material>
          <diffuse>0.3125 0.3125 0.3125 1</diffuse>
          <ambient>0.3125 0.3125 0.3125 1</ambient>
        </material>
      </visual>
      <visual name='base_footprint_fixed_joint_lump__tripod_ring_visual_visual_5'>
        <pose>0.77000000000000002 0 1.508 0 0 0</pose>
        <geometry>
          <mesh>
            <scale>1 1 1</scale>
            <uri>file:///home/luca002/proj_ws/src/wamv_gazebo/models/wam-v/meshes/ring.dae</uri>
          </mesh>
        </geometry>
        <material>
          <diffuse>0.81249994 0.81249994 0.875 1</diffuse>
          <ambient>0.81249994 0.81249994 0.875 1</ambient>
        </material>
      </visual>
      <visual name='base_footprint_fixed_joint_lump__lidar_visual_visual_6'>
        <pose>0.77000000000000002 0 1.518 0 0 0</pose>
        <geometry>
          <mesh>
            <scale>1 1 1</scale>
            <uri>file:///home/luca002/proj_ws/src/wamv_gazebo/models/wam-v/meshes/lidar_3d_v1.dae</uri>
          </mesh>
        </geometry>
      </visual>
      <sensor name='imu_sensor' type='imu'>
        <update_rate>100</update_rate>
        <visualize>true</visualize>
        <topic>imu</topic>
        <imu>
          <angular_velocity>
            <x>
              <noise type='gaussian'>
                <mean>0</mean>
                <stddev>0.0089999999999999993</stddev>
                <bias_mean>0.00075000000000000002</bias_mean>
                <bias_stddev>0.0050000000000000001</bias_stddev>
                <dynamic_bias_stddev>2.0000000000000002e-05</dynamic_bias_stddev>
                <dynamic_bias_correlation_time>400</dynamic_bias_correlation_time>
                <precision>0.00025000000000000001</precision>
              </noise>
            </x>
            <y>
              <noise type='gaussian'>
                <mean>0</mean>
                <stddev>0.0089999999999999993</stddev>
                <bias_mean>0.00075000000000000002</bias_mean>
                <bias_stddev>0.0050000000000000001</bias_stddev>
                <dynamic_bias_stddev>2.0000000000000002e-05</dynamic_bias_stddev>
                <dynamic_bias_correlation_time>400</dynamic_bias_correlation_time>
                <precision>0.00025000000000000001</precision>
              </noise>
            </y>
            <z>
              <noise type='gaussian'>
                <mean>0</mean>
                <stddev>0.0089999999999999993</stddev>
                <bias_mean>0.00075000000000000002</bias_mean>
                <bias_stddev>0.0050000000000000001</bias_stddev>
                <dynamic_bias_stddev>2.0000000000000002e-05</dynamic_bias_stddev>
                <dynamic_bias_correlation_time>400</dynamic_bias_correlation_time>
                <precision>0.00025000000000000001</precision>
              </noise>
            </z>
          </angular_velocity>
          <linear_acceleration>
            <x>
              <noise type='gaussian'>
                <mean>0</mean>
                <stddev>0.021000000000000001</stddev>
                <bias_mean>0.050000000000000003</bias_mean>
                <bias_stddev>0.0074999999999999997</bias_stddev>
                <dynamic_bias_stddev>0.00037500000000000001</dynamic_bias_stddev>
                <dynamic_bias_correlation_time>175</dynamic_bias_correlation_time>
                <precision>0.0050000000000000001</precision>
              </noise>
            </x>
            <y>
              <noise type='gaussian'>
                <mean>0</mean>
                <stddev>0.021000000000000001</stddev>
                <bias_mean>0.050000000000000003</bias_mean>
                <bias_stddev>0.0074999999999999997</bias_stddev>
                <dynamic_bias_stddev>0.00037500000000000001</dynamic_bias_stddev>
                <dynamic_bias_correlation_time>175</dynamic_bias_correlation_time>
                <precision>0.0050000000000000001</precision>
              </noise>
            </y>
            <z>
              <noise type='gaussian'>
                <mean>0</mean>
                <stddev>0.021000000000000001</stddev>
                <bias_mean>0.050000000000000003</bias_mean>
                <bias_stddev>0.0074999999999999997</bias_stddev>
                <dynamic_bias_stddev>0.00037500000000000001</dynamic_bias_stddev>
                <dynamic_bias_correlation_time>175</dynamic_bias_correlation_time>
                <precision>0.0050000000000000001</precision>
              </noise>
            </z>
          </linear_acceleration>
        </imu>
        <pose>0.072999999999999995 0 1.3 0 0 0</pose>
      </sensor>
      <sensor name='gpu_lidar' type='gpu_lidar'>
        <update_rate>5</update_rate>
        <topic>scan</topic>
        <always_on>true</always_on>
        <visualize>true</visualize>
        <ray>
          <scan>
            <horizontal>
              <samples>640</samples>
              <resolution>1</resolution>
              <min_angle>-1.396263</min_angle>
              <max_angle>1.396263</max_angle>
            </horizontal>
            <vertical>
              <samples>16</samples>
              <resolution>1</resolution>
              <min_angle>-0.26179000000000002</min_angle>
              <max_angle>0.26179000000000002</max_angle>
            </vertical>
          </scan>
          <range>
            <min>0.10000000000000001</min>
            <max>30</max>
            <resolution>0.01</resolution>
          </range>
          <noise>
            <type>gaussian</type>
            <mean>0</mean>
            <stddev>0.01</stddev>
          </noise>
        </ray>
        <pose>0.77000000000000002 0 1.554 0 0.139626 0</pose>
      </sensor>
      <sensor name='gps_sensor' type='gps'>
        <always_on>true</always_on>
        <update_rate>1</update_rate>
        <visualize>true</visualize>
        <topic>fix</topic>
        <gps>
          <position_sensing>
            <horizontal>
              <noise type='gaussian'>
                <mean>0</mean>
                <stddev>9.9999999999999995e-07</stddev>
              </noise>
            </horizontal>
            <vertical>
              <noise type='gaussian'>
                <mean>0</mean>
                <stddev>9.9999999999999995e-07</stddev>
              </noise>
            </vertical>
          </position_sensing>
        </gps>
        <pose>0.77000000000000002 0 1.518 0 0 0</pose>
      </sensor>
    </link>
    <joint name='left_chassis_engine_joint' type='revolute'>
      <pose relative_to='base_footprint'>-2.3737759999999999 1.0271349999999999 0.31823699999999999 0 0 0</pose>
      <parent>base_footprint</parent>
      <child>left_engine_link</child>
      <axis>
        <xyz>0 0 1</xyz>
        <limit>
          <lower>-1.5707899999999999</lower>
          <upper>1.5707899999999999</upper>
          <effort>10</effort>
          <velocity>10</velocity>
        </limit>
        <dynamics>
          <spring_reference>0</spring_reference>
          <spring_stiffness>0</spring_stiffness>
        </dynamics>
      </axis>
    </joint>
    <link name='left_engine_link'>
      <pose relative_to='left_chassis_engine_joint'>0 0 0 0 0 0</pose>
      <inertial>
        <pose>0 0 0 0 0 0</pose>
        <mass>15</mass>
        <inertia>
          <ixx>0.88924499999999995</ixx>
          <ixy>0</ixy>
          <ixz>0</ixz>
          <iyy>0.81112499999999998</iyy>
          <iyz>0</iyz>
          <izz>0.078125</izz>
        </inertia>
      </inertial>
      <collision name='left_engine_link_collision'>
        <pose>-0.14499999999999999 0 -0.27000000000000002 0 0 0</pose>
        <geometry>
          <box>
            <size>0.25 0.14999999999999999 0.90000000000000002</size>
          </box>
        </geometry>
      </collision>
      <collision name='left_engine_link_collision_1'>
        <pose>-0.34000000000000002 0 0.12 0 0 0</pose>
        <geometry>
          <box>
            <size>0.14000000000000001 0.14999999999999999 0.12</size>
          </box>
        </geometry>
      </collision>
      <visual name='left_engine_link_visual'>
        <pose>0 0 0 0 0 0</pose>
        <geometry>
          <mesh>
            <scale>1 1 1</scale>
            <uri>file:///home/luca002/proj_ws/src/wamv_gazebo/models/wam-v/meshes/engine.dae</uri>
          </mesh>
        </geometry>
      </visual>
    </link>
    <joint name='left_engine_propeller_joint' type='revolute'>
      <pose relative_to='left_engine_link'>-0.27815600000000001 0 -0.50937100000000002 0 0 0</pose>
      <parent>left_engine_link</parent>
      <child>left_propeller_link</child>
      <axis>
        <xyz>1 0 0</xyz>
        <limit>
          <lower>-999999</lower>
          <upper>999999</upper>
          <effort>100</effort>
          <velocity>100</velocity>
        </limit>
        <dynamics>
          <damping>0.050000000000000003</damping>
          <friction>0.050000000000000003</friction>
          <spring_reference>0</spring_reference>
          <spring_stiffness>0</spring_stiffness>
        </dynamics>
      </axis>
    </joint>
    <link name='left_propeller_link'>
      <pose relative_to='left_engine_propeller_joint'>0 0 0 0 0 0</pose>
      <inertial>
        <pose>0 0 0 0 0 0</pose>
        <mass>0.5</mass>
        <inertia>
          <ixx>0.0085450000000000005</ixx>
          <ixy>0</ixy>
          <ixz>0</ixz>
          <iyy>0.0085450000000000005</iyy>
          <iyz>0</iyz>
          <izz>0.0144</izz>
        </inertia>
      </inertial>
      <collision name='left_propeller_link_collision'>
        <pose>-0.080000000000000002 0 0 0 1.5707963267948966 0</pose>
        <geometry>
          <cylinder>
            <length>0.17999999999999999</length>
            <radius>0.23999999999999999</radius>
          </cylinder>
        </geometry>
      </collision>
      <visual name='left_propeller_link_visual'>
        <pose>0 0 0 0 0 0</pose>
        <geometry>
          <mesh>
            <scale>1 1 1</scale>
            <uri>file:///home/luca002/proj_ws/src/wamv_gazebo/models/wam-v/meshes/propeller.dae</uri>
          </mesh>
        </geometry>
      </visual>
    </link>
    <joint name='right_chassis_engine_joint' type='revolute'>
      <pose relative_to='base_footprint'>-2.3737759999999999 -1.0271349999999999 0.31823699999999999 0 0 0</pose>
      <parent>base_footprint</parent>
      <child>right_engine_link</child>
      <axis>
        <xyz>0 0 1</xyz>
        <limit>
          <lower>-1.5707899999999999</lower>
          <upper>1.5707899999999999</upper>
          <effort>10</effort>
          <velocity>10</velocity>
        </limit>
        <dynamics>
          <spring_reference>0</spring_reference>
          <spring_stiffness>0</spring_stiffness>
        </dynamics>
      </axis>
    </joint>
    <link name='right_engine_link'>
      <pose relative_to='right_chassis_engine_joint'>0 0 0 0 0 0</pose>
      <inertial>
        <pose>0 0 0 0 0 0</pose>
        <mass>15</mass>
        <inertia>
          <ixx>0.88924499999999995</ixx>
          <ixy>0</ixy>
          <ixz>0</ixz>
          <iyy>0.81112499999999998</iyy>
          <iyz>0</iyz>
          <izz>0.078125</izz>
        </inertia>
      </inertial>
      <collision name='right_engine_link_collision'>
        <pose>-0.14499999999999999 0 -0.27000000000000002 0 0 0</pose>
        <geometry>
          <box>
            <size>0.25 0.14999999999999999 0.90000000000000002</size>
          </box>
        </geometry>
      </collision>
      <collision name='right_engine_link_collision_1'>
        <pose>-0.34000000000000002 0 0.12 0 0 0</pose>
        <geometry>
          <box>
            <size>0.14000000000000001 0.14999999999999999 0.12</size>
          </box>
        </geometry>
      </collision>
      <visual name='right_engine_link_visual'>
        <pose>0 0 0 0 0 0</pose>
        <geometry>
          <mesh>
            <scale>1 1 1</scale>
            <uri>file:///home/luca002/proj_ws/src/wamv_gazebo/models/wam-v/meshes/engine.dae</uri>
          </mesh>
        </geometry>
      </visual>
    </link>
    <joint name='right_engine_propeller_joint' type='revolute'>
      <pose relative_to='right_engine_link'>-0.27815600000000001 0 -0.50937100000000002 0 0 0</pose>
      <parent>right_engine_link</parent>
      <child>right_propeller_link</child>
      <axis>
        <xyz>1 0 0</xyz>
        <limit>
          <lower>-999999</lower>
          <upper>999999</upper>
          <effort>100</effort>
          <velocity>100</velocity>
        </limit>
        <dynamics>
          <damping>0.050000000000000003</damping>
          <friction>0.050000000000000003</friction>
          <spring_reference>0</spring_reference>
          <spring_stiffness>0</spring_stiffness>
        </dynamics>
      </axis>
    </joint>
    <link name='right_propeller_link'>
      <pose relative_to='right_engine_propeller_joint'>0 0 0 0 0 0</pose>
      <inertial>
        <pose>0 0 0 0 0 0</pose>
        <mass>0.5</mass>
        <inertia>
          <ixx>0.0085450000000000005</ixx>
          <ixy>0</ixy>
          <ixz>0</ixz>
          <iyy>0.0085450000000000005</iyy>
          <iyz>0</iyz>
          <izz>0.0144</izz>
        </inertia>
      </inertial>
      <collision name='right_propeller_link_collision'>
        <pose>-0.080000000000000002 0 0 0 1.5707963267948966 0</pose>
        <geometry>
          <cylinder>
            <length>0.17999999999999999</length>
            <radius>0.23999999999999999</radius>
          </cylinder>
        </geometry>
      </collision>
      <visual name='right_propeller_link_visual'>
        <pose>0 0 0 0 0 0</pose>
        <geometry>
          <mesh>
            <scale>1 1 1</scale>
            <uri>file:///home/luca002/proj_ws/src/wamv_gazebo/models/wam-v/meshes/propeller.dae</uri>
          </mesh>
        </geometry>
      </visual>
    </link>
    <plugin name='gz::sim::systems::Thruster' filename='gz-sim-thruster-system'>
      <joint_name>left_engine_propeller_joint</joint_name>
      <thrust_coefficient>0.004422</thrust_coefficient>
      <fluid_density>1000</fluid_density>
      <propeller_diameter>0.2</propeller_diameter>
      <velocity_control>true</velocity_control>
    </plugin>
    <plugin name='gz::sim::systems::JointPositionController' filename='gz-sim-joint-position-controller-system'>
      <joint_name>left_chassis_engine_joint</joint_name>
      <use_velocity_commands>true</use_velocity_commands>
      <topic>/wamv/left/thruster/joint/cmd_pos</topic>
    </plugin>
    <plugin name='gz::sim::systems::Thruster' filename='gz-sim-thruster-system'>
      <joint_name>right_engine_propeller_joint</joint_name>
      <thrust_coefficient>0.004422</thrust_coefficient>
      <fluid_density>1000</fluid_density>
      <propeller_diameter>0.2</propeller_diameter>
      <velocity_control>true</velocity_control>
    </plugin>
    <plugin name='gz::sim::systems::JointPositionController' filename='gz-sim-joint-position-controller-system'>
      <joint_name>right_chassis_engine_joint</joint_name>
      <use_velocity_commands>true</use_velocity_commands>
      <topic>/wamv/right/thruster/joint/cmd_pos</topic>
    </plugin>
    <plugin name='wamv_gazebo::Surface' filename='libSurface.so'>
      <link_name>base_footprint</link_name>
      <hull_length>4.9</hull_length>
      <hull_radius>0.213</hull_radius>
      <fluid_level>0</fluid_level>
      <points>
        <point>0.6 1.03 0</point>
        <point>-1.4 1.03 0</point>
      </points>
      <wavefield>
        <topic>/wamv_gazebo/wavefield/parameters</topic>
      </wavefield>
    </plugin>
    <plugin name='wamv_gazebo::Surface' filename='libSurface.so'>
      <link_name>base_footprint</link_name>
      <hull_length>4.9</hull_length>
      <hull_radius>0.213</hull_radius>
      <fluid_level>0</fluid_level>
      <points>
        <point>0.6 -1.03 0</point>
        <point>-1.4 -1.03 0</point>
      </points>
      <wavefield>
        <topic>/wamv_gazebo/wavefield/parameters</topic>
      </wavefield>
    </plugin>
    <plugin name='gz::sim::systems::Hydrodynamics' filename='gz-sim-hydrodynamics-system'>
      <link_name>base_footprint</link_name>
      <xDotU>0.0</xDotU>
      <yDotV>0.0</yDotV>
      <nDotR>0.0</nDotR>
      <xU>-51.3</xU>
      <xAbsU>-72.4</xAbsU>
      <yV>-40.0</yV>
      <yAbsV>0.0</yAbsV>
      <zW>-500.0</zW>
      <kP>-50.0</kP>
      <mQ>-50.0</mQ>
      <nR>-400.0</nR>
      <nAbsR>0.0</nAbsR>
    </plugin>
    <plugin name='gz::sim::systems::OdometryPublisher' filename='libgz-sim-odometry-publisher-system.so'>
      <odom_topic>odom</odom_topic>
      <frame_id>odom</frame_id>
      <child_frame_id>base_footprint</child_frame_id>
      <tf_topic>tf</tf_topic>
      <publish_tf>true</publish_tf>
      <odom_publish_frequency>30</odom_publish_frequency>
    </plugin>
    <frame name='battery_dx_joint' attached_to='base_link'>
      <pose>-0.13 -1.0289999999999999 0.44800000000000001 0 0 0</pose>
    </frame>
    <frame name='battery_dx_link' attached_to='battery_dx_joint'>
      <pose>0 0 0 0 0 0</pose>
    </frame>
    <frame name='battery_sx_joint' attached_to='base_link'>
      <pose>-0.13 1.0289999999999999 0.44800000000000001 0 0 0</pose>
    </frame>
    <frame name='battery_sx_link' attached_to='battery_sx_joint'>
      <pose>0 0 0 0 0 0</pose>
    </frame>
    <frame name='cpu_cases_joint' attached_to='base_link'>
      <pose>0.072999999999999995 0 1.3 0 0 0</pose>
    </frame>
    <frame name='cpu_cases_link' attached_to='cpu_cases_joint'>
      <pose>0 0 0 0 0 0</pose>
    </frame>
    <frame name='lidar_joint' attached_to='tripod_ring_link'>
      <pose>0 0 0.01 0 0 0</pose>
    </frame>
    <frame name='lidar_link' attached_to='lidar_joint'>
      <pose>0 0 0 0 0 0</pose>
    </frame>
    <frame name='tripod_ring_joint' attached_to='tripod_legs_link'>
      <pose>0 0 0.218 0 0 0</pose>
    </frame>
    <frame name='tripod_ring_link' attached_to='tripod_ring_joint'>
      <pose>0 0 0 0 0 0</pose>
    </frame>
    <frame name='tripod_legs_joint' attached_to='base_link'>
      <pose>0.77000000000000002 0 1.29 0 0 0</pose>
    </frame>
    <frame name='tripod_legs_link' attached_to='tripod_legs_joint'>
      <pose>0 0 0 0 0 0</pose>
    </frame>
    <frame name='base_footprint_joint' attached_to='base_footprint'>
      <pose>0 0 0 0 0 0</pose>
    </frame>
    <frame name='base_link' attached_to='base_footprint_joint'>
      <pose>0 0 0 0 0 0</pose>
    </frame>
  </model>
</sdf>